Workbook
Name 이름이지정된범위1: '▧ 26년 휴가대장'!$1:$52
Name 이름이지정된범위1: #REF!
Name 휴가_월_1: '▧ 26년 휴가대장'!$A$2
Name 퍼블_월_1: '▧ 26년 퍼블대장'!$B$3
Name 퍼블_월_6: #REF!
Name 퍼블_년: '▧ 26년 퍼블대장'!$B$2
Name 휴가_월_1: #REF!
Name 공휴일: #REF!
Name 퍼블_월_1: #REF!
Name 공휴일: '▧ 26년 퍼블대장'!$D$5:$D$27
Name 휴가_월_6: #REF!
Name 휴가_년: #REF!
Name 휴가_년: '▧ 26년 휴가대장'!$A$1
Name 퍼블_년: #REF!
Name 퍼블_월_6: '▧ 26년 퍼블대장'!$B$4
Name 휴가_월_6: '▧ 26년 휴가대장'!$A$3

Sheet 구분
A1: 대분류 | B1: 중분류 | C1: 진행현황 | D1: 구분 | E1: 배포/반영 | F1: 중분류 | H1: 퍼블진행형황 | J1: 기업/글로벌로밍 소분류 | K1: 구분
A2: SP1 | B2: 공통 | C2: 예정 | D2: 신규 | E2: 배포 | F2: 기업 | H2: 예정 | J2: 공통 | K2: SP1
A3: SP2 | B3: 메인 | C3: 접수 | D3: 수정 | E3: 반영 | F3: 소상공인 | H3: 진행 | J3: 상품서비스 | K3: SP2
A4: SP3 | B4: 모바일기기 | C4: 검토 | D4: 기타 | E4: 이미지만 | F4: 글로벌로밍 | H4: 보류 | J4: 진행중인 이벤트 | K4: SP3
A5: 공통 | B5: 유심/eSIM | C5: 대기 | H5: 검수요청 | J5: 비즈인사이트 | K5: 공통
B6: 액세서리 | C6: 진행 | H6: 반영대기 | J6: 마이페이지
B7: 유플러스 LIVE | C7: 검수 | H7: 완료 | J7: 고객지원
B8: 모바일요금제 | C8: 완료 | J8: SOHO 메인
B9: 인터넷/IPTV | C9: 보류 | J9: SOHO 상세
B10: MY | C10: 취소 | J10: 자사채널배너
B11: 혜택 | J11: 외부채널
B12: 이벤트 | J12: 개인화마케팅
B13: 이벤트(모바일/홈) | J13: 사장님광장
B14: 고객지원 | J14: 인바운드로밍
B15: 회사소개 | J15: 아웃바운드로밍
B16: 고객센터(앱) | J16: 로밍상품권
B17: 개인화 | J17: 외국인페이지
B18: 분석
B19: 임직원 몰
B20: 예약 판매(가입)
B21: 개선
B22: 다이렉트
B23: 유쓰
B24: SI지원
B25: 기타
B26: 관리
A39: 대분류 | B39: SP1 | C39: 서비스 파트 1 : 신태민 님 담당 파트
B40: SP2 | C40: 서비스 파트 2 : 조두환 님 담당 파트
B41: SP3 | C41: 서비스 파트 3 : 도현진 님 담당 파트 (개인화)
A42: 중분류 | B42: 공통 | C42: GNB, 로그인, 장바구니, 검색, 푸터
B43: 메인
B44: 모바일기기 | C44: 5G/4G 휴대폰, 태블릿, 스마트워치, 노트북, 중고/자급제폰, 간편기기변경, 모델별지원금, 가입예판
B45: 유심
B46: 액세서리
B47: 유플러스 LIVE
B48: 모바일요금제
B49: 인터넷/IPTV
B50: MY
B51: 혜택 | C51: 이벤트 외 혜택 메뉴
B52: 이벤트 | C52: 디지털CX 담당, 전사 요청
...

Sheet ▧ 26년 휴가대장
A1: 2026
A2: 1
A3: 6
A4: 신정 | B4: 46023
A5: 설날 | B5: 46069
B6: 46070
B7: 46071
A8: 삼일절 | B8: 46082
B9: 46083
A10: 창립기념일 | B10: 46122
A11: 근로자의날 | B11: 46143
A12: 어린이날 | B12: 46147
A13: 석가탄신일 | B13: 46166
B14: 46167
A15: 현충일 | B15: 46179
A16: 광복절 | B16: 46249
B17: 46251
A18: 추석 | B18: 46289
B19: 46290
A20: 개천절 | B20: 46298
B21: 46300
A22: 한글날 | B22: 46304
A23: 크리스마스 | B23: 46381
A24: 2026년 휴가대장
A25: ="오늘은 " & month(TODAY()) &"월 " & day(today())&"일 " & choose(weekday(today()),"일","월","화","수","목","금","토")&"요일 입니다." -> 오늘은 9월 9일 수요일 입니다.
A26: ★ 휴가는 해당일에 '휴'로 표시 합니다. 반차는 '전, 후' 반반차는 '반'으로 적으세요.
A27: ● 문서 관리자 : (현장대리인) 한수빈, 홍성호, 최정규
G29: 1월 | AL29: 2월 | BN29: 3월 | CS29: 4월 | DW29: 5월 | FB29: 6월 | GF29: 7월 | HK29: 8월 | IP29: 9월 | JT29: 10월 | KY29: 11월 | MC29: 12월
A30: 주요일정 | G30: ▼새해 | BB30: ▼설날 | BN30: ▼3.1절 | DB30: ▼창립기념일 | DW30: ▼근로자의날 | EA30: ▼어린이날 | ET30: ▼부처님오신날 | FD30: ▼지방선거 | FG30: ▼현충일 | HY30: ▼광복절 | JN30: ▼추석 | JV30: ▼개천절 | KB30: ▼한글날 | NA30: ▼크리스마스
A31: NO | B31: 이름 | F31: 합계 | G31: =IF(DATE('▧ 26년 휴가대장'!휴가_년, '▧ 26년 휴가대장'!휴가_월_1, COLUMN()-6) > EOMONTH(DATE('▧ 26년 휴가대장'!휴가_년, '▧ 26년 휴가대장'!휴가_월_1, 1), 6), "", DATE('▧ 26년 휴가대장'!휴가_년, '▧ 26년 휴가대장'!휴가_월_1, COLUMN()-6)) -> 46023 | H31: =IF(DATE('▧ 26년 휴가대장'!휴가_년, '▧ 26년 휴가대장'!휴가_월_1, COLUMN()-6) > EOMONTH(DATE('▧ 26년 휴가대장'!휴가_년, '▧ 26년 휴가대장'!휴가_월_1, 1), 6), "", DATE('▧ 26년 휴가대장'!휴가_년, '▧ 26년 휴가대장'!휴가_월_1, COLUMN()-6)) -> 46024 | I31: =IF(DATE('▧ 26년 휴가대장'!휴가_년, '▧ 26년 휴가대장'!휴가_월_1, COLUMN()-6) > EOMONTH(DATE('▧ 26년 휴가대장'!휴가_년, '▧ 26년 휴가대장'!휴가_월_1, 1), 6), "", DATE('▧ 26년 휴가대장'!휴가_년, '▧ 26년 휴가대장'!휴가_월_1, COLUMN()-6)) -> 46025 | J31: =IF(DATE('▧ 26년 휴가대장'!휴가_년, '▧ 26년 휴가대장'!휴가_월_1, COLUMN()-6) > EOMONTH(DATE('▧ 26년 휴가대장'!휴가_년, '▧ 26년 휴가대장'!휴가_월_1, 1), 6), "", DATE('▧ 26년 휴가대장'!휴가_년, '▧ 26년 휴가대장'!휴가_월_1, COLUMN()-6)) -> 46026 | K31: =IF(DATE('▧ 26년 휴가대장'!휴가_년, '▧ 26년 휴가대장'!휴가_월_1, COLUMN()-6) > EOMONTH(DATE('▧ 26년 휴가대장'!휴가_년, '▧ 26년 휴가대장'!휴가_월_1, 1), 6), "", DATE('▧ 26년 휴가대장'!휴가_년, '▧ 26년 휴가대장'!휴가_월_1, COLUMN()-6)) -> 46027 | L31: =IF(DATE('▧ 26년 휴가대장'!휴가_년, '▧ 26년 휴가대장'!휴가_월_1, COLUMN()-6) > EOMONTH(DATE('▧ 26년 휴가대장'!휴가_년, '▧ 26년 휴가대장'!휴가_월_1, 1), 6), "", DATE('▧ 26년 휴가대장'!휴가_년, '▧ 26년 휴가대장'!휴가_월_1, COLUMN()-6)) -> 46028 | M31: =IF(DATE('▧ 26년 휴가대장'!휴가_년, '▧ 26년 휴가대장'!휴가_월_1, COLUMN()-6) > EOMONTH(DATE('▧ 26년 휴가대장'!휴가_년, '▧ 26년 휴가대장'!휴가_월_1, 1), 6), "", DATE('▧ 26년 휴가대장'!휴가_년, '▧ 26년 휴가대장'!휴가_월_1, COLUMN()-6)) -> 46029 | N31: =IF(DATE('▧ 26년 휴가대장'!휴가_년, '▧ 26년 휴가대장'!휴가_월_1, COLUMN()-6) > EOMONTH(DATE('▧ 26년 휴가대장'!휴가_년, '▧ 26년 휴가대장'!휴가_월_1, 1), 6), "", DATE('▧ 26년 휴가대장'!휴가_년, '▧ 26년 휴가대장'!휴가_월_1, COLUMN()-6)) -> 46030 | ... GE31: =IF(DATE('▧ 26년 휴가대장'!휴가_년, '▧ 26년 휴가대장'!휴가_월_1, COLUMN()-6) > EOMONTH(DATE('▧ 26년 휴가대장'!휴가_년, '▧ 26년 휴가대장'!휴가_월_1, 1), 6), "", DATE('▧ 26년 휴가대장'!휴가_년, '▧ 26년 휴가대장'!휴가_월_1, COLUMN()-6)) -> 46203 | GF31: =IF(DATE('▧ 26년 휴가대장'!휴가_년,'▧ 26년 휴가대장'!휴가_월_6,COLUMN()-157)>DATE('▧ 26년 휴가대장'!휴가_년,'▧ 26년 휴가대장'!휴가_월_6+157,0),"",DATE('▧ 26년 휴가대장'!휴가_년,'▧ 26년 휴가대장'!휴가_월_6,COLUMN()-157)) -> 46204 | GG31: =IF(DATE('▧ 26년 휴가대장'!휴가_년,'▧ 26년 휴가대장'!휴가_월_6,COLUMN()-157)>DATE('▧ 26년 휴가대장'!휴가_년,'▧ 26년 휴가대장'!휴가_월_6+157,0),"",DATE('▧ 26년 휴가대장'!휴가_년,'▧ 26년 휴가대장'!휴가_월_6,COLUMN()-157)) -> 46205 | GH31: =IF(DATE('▧ 26년 휴가대장'!휴가_년,'▧ 26년 휴가대장'!휴가_월_6,COLUMN()-157)>DATE('▧ 26년 휴가대장'!휴가_년,'▧ 26년 휴가대장'!휴가_월_6+157,0),"",DATE('▧ 26년 휴가대장'!휴가_년,'▧ 26년 휴가대장'!휴가_월_6,COLUMN()-157)) -> 46206 | GI31: =IF(DATE('▧ 26년 휴가대장'!휴가_년,'▧ 26년 휴가대장'!휴가_월_6,COLUMN()-157)>DATE('▧ 26년 휴가대장'!휴가_년,'▧ 26년 휴가대장'!휴가_월_6+157,0),"",DATE('▧ 26년 휴가대장'!휴가_년,'▧ 26년 휴가대장'!휴가_월_6,COLUMN()-157)) -> 46207 | GJ31: =IF(DATE('▧ 26년 휴가대장'!휴가_년,'▧ 26년 휴가대장'!휴가_월_6,COLUMN()-157)>DATE('▧ 26년 휴가대장'!휴가_년,'▧ 26년 휴가대장'!휴가_월_6+157,0),"",DATE('▧ 26년 휴가대장'!휴가_년,'▧ 26년 휴가대장'!휴가_월_6,COLUMN()-157)) -> 46208 | GK31: =IF(DATE('▧ 26년 휴가대장'!휴가_년,'▧ 26년 휴가대장'!휴가_월_6,COLUMN()-157)>DATE('▧ 26년 휴가대장'!휴가_년,'▧ 26년 휴가대장'!휴가_월_6+157,0),"",DATE('▧ 26년 휴가대장'!휴가_년,'▧ 26년 휴가대장'!휴가_월_6,COLUMN()-157)) -> 46209 | GL31: =IF(DATE('▧ 26년 휴가대장'!휴가_년,'▧ 26년 휴가대장'!휴가_월_6,COLUMN()-157)>DATE('▧ 26년 휴가대장'!휴가_년,'▧ 26년 휴가대장'!휴가_월_6+157,0),"",DATE('▧ 26년 휴가대장'!휴가_년,'▧ 26년 휴가대장'!휴가_월_6,COLUMN()-157)) -> 46210 | GM31: =IF(DATE('▧ 26년 휴가대장'!휴가_년,'▧ 26년 휴가대장'!휴가_월_6,COLUMN()-157)>DATE('▧ 26년 휴가대장'!휴가_년,'▧ 26년 휴가대장'!휴가_월_6+157,0),"",DATE('▧ 26년 휴가대장'!휴가_년,'▧ 26년 휴가대장'!휴가_월_6,COLUMN()-157)) -> 46211 | ... NG31: =IF(DATE('▧ 26년 휴가대장'!휴가_년,'▧ 26년 휴가대장'!휴가_월_6,COLUMN()-157)>DATE('▧ 26년 휴가대장'!휴가_년,'▧ 26년 휴가대장'!휴가_월_6+157,0),"",DATE('▧ 26년 휴가대장'!휴가_년,'▧ 26년 휴가대장'!휴가_월_6,COLUMN()-157)) -> 46387
G32: =G31 -> 46023 | H32: =H31 -> 46024 | I32: =I31 -> 46025 | J32: =J31 -> 46026 | K32: =K31 -> 46027 | L32: =L31 -> 46028 | M32: =M31 -> 46029 | N32: =N31 -> 46030 | ... NG32: =NG31 -> 46387
A33: 1 | B33: 우승연 | F33: =SUMPRODUCT(IF(('▧ 26년 휴가대장'!$G33:$NG33<>"") * (('▧ 26년 휴가대장'!$G33:$NG33="전") + ('▧ 26년 휴가대장'!$G33:$NG33="후")), 0.5, IF('▧ 26년 휴가대장'!$G33:$NG33="반", 0.25, IF('▧ 26년 휴가대장'!$G33:$NG33="휴", 1, 0)))) & " 일" -> 0 일
A34: 2 | B34: 김정주 | F34: =SUMPRODUCT(IF(('▧ 26년 휴가대장'!$G34:$NG34<>"") * (('▧ 26년 휴가대장'!$G34:$NG34="전") + ('▧ 26년 휴가대장'!$G34:$NG34="후")), 0.5, IF('▧ 26년 휴가대장'!$G34:$NG34="반", 0.25, IF('▧ 26년 휴가대장'!$G34:$NG34="휴", 1, 0)))) & " 일" -> 0 일
A35: 3 | B35: 조아해 | F35: =SUMPRODUCT(IF(('▧ 26년 휴가대장'!$G35:$NG35<>"") * (('▧ 26년 휴가대장'!$G35:$NG35="전") + ('▧ 26년 휴가대장'!$G35:$NG35="후")), 0.5, IF('▧ 26년 휴가대장'!$G35:$NG35="반", 0.25, IF('▧ 26년 휴가대장'!$G35:$NG35="휴", 1, 0)))) & " 일" -> 0 일
A36: 4 | B36: 박중현 | F36: =SUMPRODUCT(IF(('▧ 26년 휴가대장'!$G36:$NG36<>"") * (('▧ 26년 휴가대장'!$G36:$NG36="전") + ('▧ 26년 휴가대장'!$G36:$NG36="후")), 0.5, IF('▧ 26년 휴가대장'!$G36:$NG36="반", 0.25, IF('▧ 26년 휴가대장'!$G36:$NG36="휴", 1, 0)))) & " 일" -> 0 일
A37: 5 | B37: 장원희 | F37: =SUMPRODUCT(IF(('▧ 26년 휴가대장'!$G37:$NG37<>"") * (('▧ 26년 휴가대장'!$G37:$NG37="전") + ('▧ 26년 휴가대장'!$G37:$NG37="후")), 0.5, IF('▧ 26년 휴가대장'!$G37:$NG37="반", 0.25, IF('▧ 26년 휴가대장'!$G37:$NG37="휴", 1, 0)))) & " 일" -> 0 일
A38: 6 | B38: 한수빈팀장 | F38: =SUMPRODUCT(IF(('▧ 26년 휴가대장'!$KY38:$NG38<>"") * (('▧ 26년 휴가대장'!$KY38:$NG38="전") + ('▧ 26년 휴가대장'!$KY38:$NG38="후")), 0.5, IF('▧ 26년 휴가대장'!$KY38:$NG38="반", 0.25, IF('▧ 26년 휴가대장'!$KY38:$NG38="휴", 1, 0)))) & " 일" -> 0 일
A39: 7 | B39: 김아랑책임 | F39: =SUMPRODUCT(IF(('▧ 26년 휴가대장'!$G39:$NG39<>"") * (('▧ 26년 휴가대장'!$G39:$NG39="전") + ('▧ 26년 휴가대장'!$G39:$NG39="후")), 0.5, IF('▧ 26년 휴가대장'!$G39:$NG39="반", 0.25, IF('▧ 26년 휴가대장'!$G39:$NG39="휴", 1, 0)))) & " 일" -> 0 일
A40: 8 | B40: 이현미책임 | F40: =SUMPRODUCT(IF(('▧ 26년 휴가대장'!$KY40:$NG40<>"") * (('▧ 26년 휴가대장'!$KY40:$NG40="전") + ('▧ 26년 휴가대장'!$KY40:$NG40="후")), 0.5, IF('▧ 26년 휴가대장'!$KY40:$NG40="반", 0.25, IF('▧ 26년 휴가대장'!$KY40:$NG40="휴", 1, 0)))) & " 일" -> 0 일
A41: 9 | B41: 안혜지선임 | F41: =SUMPRODUCT(IF(('▧ 26년 휴가대장'!$G41:$NG41<>"") * (('▧ 26년 휴가대장'!$G41:$NG41="전") + ('▧ 26년 휴가대장'!$G41:$NG41="후")), 0.5, IF('▧ 26년 휴가대장'!$G41:$NG41="반", 0.25, IF('▧ 26년 휴가대장'!$G41:$NG41="휴", 1, 0)))) & " 일" -> 0 일
...

Sheet ▧ 26년 퍼블대장
A1: ▧ 2026년 퍼블대장
A2: 2026
A3: 1
A4: 6
A5: 신정 | B5: 46023
A6: 설날 | B6: 46069
B7: 46070
B8: 46071
A9: 삼일절 | B9: 46082
B10: 46083
A11: 창립기념일 | B11: 46122
A12: 근로자의날 | B12: 46143
A13: 어린이날 | B13: 46147
A14: 석가탄신일 | B14: 46166
B15: 46167
A16: 지방선거 | B16: 46176
A17: 현충일 | B17: 46179
A18: 제헌절 | B18: 46220
A19: 광복절 | B19: 46249
B20: 46251
A21: 추석 | B21: 46289
B22: 46290
A23: 개천절 | B23: 46298
B24: 46300
A25: 한글날 | B25: 46304
A26: 크리스마스 | B26: 46381
F28: 1월 | AK28: 2월 | BM28: 3월 | CR28: 4월 | DV28: 5월 | FA28: 6월 | GE28: 7월 | HJ28: 8월 | IO28: 9월 | JS28: 10월 | KX28: 11월 | MB28: 12월
E29: 주요일정 | F29: ▼새해 | BA29: ▼설날 | BM29: ▼3.1절 | DA29: ▼창립기념일 | DV29: ▼근로자의날 | DZ29: ▼어린이날 | ES29: ▼부처님오신날 | FC29: ▼지방선거 | FF29: ▼현충일 | HX29: ▼광복절 | JM29: ▼추석 | JU29: ▼개천절 | KA29: ▼한글날 | MZ29: ▼크리스마스
C30: 반영일 컬러 | F30: =IF(DATE('▧ 26년 휴가대장'!휴가_년, '▧ 26년 휴가대장'!휴가_월_1, COLUMN()-5) > EOMONTH(DATE('▧ 26년 휴가대장'!휴가_년, '▧ 26년 휴가대장'!휴가_월_1, 1), 5), "", DATE('▧ 26년 휴가대장'!휴가_년, '▧ 26년 휴가대장'!휴가_월_1, COLUMN()-5)) -> 46023 | G30: =IF(DATE('▧ 26년 휴가대장'!휴가_년, '▧ 26년 휴가대장'!휴가_월_1, COLUMN()-5) > EOMONTH(DATE('▧ 26년 휴가대장'!휴가_년, '▧ 26년 휴가대장'!휴가_월_1, 1), 5), "", DATE('▧ 26년 휴가대장'!휴가_년, '▧ 26년 휴가대장'!휴가_월_1, COLUMN()-5)) -> 46024 | H30: =IF(DATE('▧ 26년 휴가대장'!휴가_년, '▧ 26년 휴가대장'!휴가_월_1, COLUMN()-5) > EOMONTH(DATE('▧ 26년 휴가대장'!휴가_년, '▧ 26년 휴가대장'!휴가_월_1, 1), 5), "", DATE('▧ 26년 휴가대장'!휴가_년, '▧ 26년 휴가대장'!휴가_월_1, COLUMN()-5)) -> 46025 | I30: =IF(DATE('▧ 26년 휴가대장'!휴가_년, '▧ 26년 휴가대장'!휴가_월_1, COLUMN()-5) > EOMONTH(DATE('▧ 26년 휴가대장'!휴가_년, '▧ 26년 휴가대장'!휴가_월_1, 1), 5), "", DATE('▧ 26년 휴가대장'!휴가_년, '▧ 26년 휴가대장'!휴가_월_1, COLUMN()-5)) -> 46026 | J30: =IF(DATE('▧ 26년 휴가대장'!휴가_년, '▧ 26년 휴가대장'!휴가_월_1, COLUMN()-5) > EOMONTH(DATE('▧ 26년 휴가대장'!휴가_년, '▧ 26년 휴가대장'!휴가_월_1, 1), 5), "", DATE('▧ 26년 휴가대장'!휴가_년, '▧ 26년 휴가대장'!휴가_월_1, COLUMN()-5)) -> 46027 | K30: =IF(DATE('▧ 26년 휴가대장'!휴가_년, '▧ 26년 휴가대장'!휴가_월_1, COLUMN()-5) > EOMONTH(DATE('▧ 26년 휴가대장'!휴가_년, '▧ 26년 휴가대장'!휴가_월_1, 1), 5), "", DATE('▧ 26년 휴가대장'!휴가_년, '▧ 26년 휴가대장'!휴가_월_1, COLUMN()-5)) -> 46028 | L30: =IF(DATE('▧ 26년 휴가대장'!휴가_년, '▧ 26년 휴가대장'!휴가_월_1, COLUMN()-5) > EOMONTH(DATE('▧ 26년 휴가대장'!휴가_년, '▧ 26년 휴가대장'!휴가_월_1, 1), 5), "", DATE('▧ 26년 휴가대장'!휴가_년, '▧ 26년 휴가대장'!휴가_월_1, COLUMN()-5)) -> 46029 | M30: =IF(DATE('▧ 26년 휴가대장'!휴가_년, '▧ 26년 휴가대장'!휴가_월_1, COLUMN()-5) > EOMONTH(DATE('▧ 26년 휴가대장'!휴가_년, '▧ 26년 휴가대장'!휴가_월_1, 1), 5), "", DATE('▧ 26년 휴가대장'!휴가_년, '▧ 26년 휴가대장'!휴가_월_1, COLUMN()-5)) -> 46030 | ... GD30: =IF(DATE('▧ 26년 휴가대장'!휴가_년, '▧ 26년 휴가대장'!휴가_월_1, COLUMN()-5) > EOMONTH(DATE('▧ 26년 휴가대장'!휴가_년, '▧ 26년 휴가대장'!휴가_월_1, 1), 5), "", DATE('▧ 26년 휴가대장'!휴가_년, '▧ 26년 휴가대장'!휴가_월_1, COLUMN()-5)) -> 46203 | GE30: =IF(DATE('▧ 26년 휴가대장'!휴가_년,'▧ 26년 휴가대장'!휴가_월_6,COLUMN()-156)>DATE('▧ 26년 휴가대장'!휴가_년,'▧ 26년 휴가대장'!휴가_월_6+156,0),"",DATE('▧ 26년 휴가대장'!휴가_년,'▧ 26년 휴가대장'!휴가_월_6,COLUMN()-156)) -> 46204 | GF30: =IF(DATE('▧ 26년 휴가대장'!휴가_년,'▧ 26년 휴가대장'!휴가_월_6,COLUMN()-156)>DATE('▧ 26년 휴가대장'!휴가_년,'▧ 26년 휴가대장'!휴가_월_6+156,0),"",DATE('▧ 26년 휴가대장'!휴가_년,'▧ 26년 휴가대장'!휴가_월_6,COLUMN()-156)) -> 46205 | GG30: =IF(DATE('▧ 26년 휴가대장'!휴가_년,'▧ 26년 휴가대장'!휴가_월_6,COLUMN()-156)>DATE('▧ 26년 휴가대장'!휴가_년,'▧ 26년 휴가대장'!휴가_월_6+156,0),"",DATE('▧ 26년 휴가대장'!휴가_년,'▧ 26년 휴가대장'!휴가_월_6,COLUMN()-156)) -> 46206 | GH30: =IF(DATE('▧ 26년 휴가대장'!휴가_년,'▧ 26년 휴가대장'!휴가_월_6,COLUMN()-156)>DATE('▧ 26년 휴가대장'!휴가_년,'▧ 26년 휴가대장'!휴가_월_6+156,0),"",DATE('▧ 26년 휴가대장'!휴가_년,'▧ 26년 휴가대장'!휴가_월_6,COLUMN()-156)) -> 46207 | GI30: =IF(DATE('▧ 26년 휴가대장'!휴가_년,'▧ 26년 휴가대장'!휴가_월_6,COLUMN()-156)>DATE('▧ 26년 휴가대장'!휴가_년,'▧ 26년 휴가대장'!휴가_월_6+156,0),"",DATE('▧ 26년 휴가대장'!휴가_년,'▧ 26년 휴가대장'!휴가_월_6,COLUMN()-156)) -> 46208 | GJ30: =IF(DATE('▧ 26년 휴가대장'!휴가_년,'▧ 26년 휴가대장'!휴가_월_6,COLUMN()-156)>DATE('▧ 26년 휴가대장'!휴가_년,'▧ 26년 휴가대장'!휴가_월_6+156,0),"",DATE('▧ 26년 휴가대장'!휴가_년,'▧ 26년 휴가대장'!휴가_월_6,COLUMN()-156)) -> 46209 | GK30: =IF(DATE('▧ 26년 휴가대장'!휴가_년,'▧ 26년 휴가대장'!휴가_월_6,COLUMN()-156)>DATE('▧ 26년 휴가대장'!휴가_년,'▧ 26년 휴가대장'!휴가_월_6+156,0),"",DATE('▧ 26년 휴가대장'!휴가_년,'▧ 26년 휴가대장'!휴가_월_6,COLUMN()-156)) -> 46210 | GL30: =IF(DATE('▧ 26년 휴가대장'!휴가_년,'▧ 26년 휴가대장'!휴가_월_6,COLUMN()-156)>DATE('▧ 26년 휴가대장'!휴가_년,'▧ 26년 휴가대장'!휴가_월_6+156,0),"",DATE('▧ 26년 휴가대장'!휴가_년,'▧ 26년 휴가대장'!휴가_월_6,COLUMN()-156)) -> 46211 | ... NF30: =IF(DATE('▧ 26년 휴가대장'!휴가_년,'▧ 26년 휴가대장'!휴가_월_6,COLUMN()-156)>DATE('▧ 26년 휴가대장'!휴가_년,'▧ 26년 휴가대장'!휴가_월_6+156,0),"",DATE('▧ 26년 휴가대장'!휴가_년,'▧ 26년 휴가대장'!휴가_월_6,COLUMN()-156)) -> 46387
B31: RMS | C31: 반영일 | D31: 업무명 | E31: 진행현황 | F31: =F30 -> 46023 | G31: =G30 -> 46024 | H31: =H30 -> 46025 | I31: =I30 -> 46026 | J31: =J30 -> 46027 | K31: =K30 -> 46028 | L31: =L30 -> 46029 | M31: =M30 -> 46030 | ... NF31: =NF30 -> 46387
B32: 82804 | C32: 46030 | D32: [DCBGIT-32743] [공통] 챗봇 : 팝업 크기 조정 관련 검토 요청의 건 | E32: 완료 | G32: 7 | J32: 2 | K32: 1
C33: 46027 | D33: [메인][플러스탭] 콘텐츠 긴급 수정_궁금했던 긴 문장, 심플하게 번역해 보세요 | E33: 완료 | G33: 1
B34: 82925 | C34: 46030 | D34: [DCBGIT-33006] [플러스탭] [진행중이벤트] 생일 파티-26년 1월 | E34: 완료 | J34: 5
B35: 82933 | C35: 46030 | D35: [메인][플러스탭] 생일 파티-26년 1월 | E35: 완료 | J35: 1 | K35: 5 | Q35: 2 | R35: 1 | S35: 1 | T35: 2
B36: 82769 | C36: 46030 | D36: [DCBGIT-32503] [검색]플러스링크 : <무너폰2> 관련 플러스링크 배너 신규 제작 요청의 건 | E36: 완료 | K36: 2
B37: 83158 | C37: 46038 | D37: [메인][플러스탭] 우리 아이 '무너폰2' 지켜줘요 | E37: 완료 | Q37: 5 | R37: 3 | S37: 4 | T37: 3 | U37: 3
B38: 83063 | C38: 46035 | D38: [DCBGIT-33381] [닷컴개발요청SR] [운영업무] 닷컴 페이지 내 랜딩 변경 요청_유독1종 | E38: 완료 | R38: 3
B39: 83112 | C39: 46038 | D39: [DCBGIT-33526] [메인] 메인KV배너(PC) : local 테스트시와 stg 환경에서 메인 배너 너비가 다르게 노출되는 건 수정 요청의 건 | E39: 완료 | S39: 3 | T39: 3
C40: 46041 | D40: [메인][플러스탭] 1월 생일 파티 이벤트 - 종료 건 딤처리 및 썸네일 타이틀 변경 | E40: 완료 | U40: 4
B41: 83172 | C41: 46052 | D41: [DCBGIT-33562] [닷컴개발요청SR] 카테고리팩 신규가입제한(AI전화팩) | E41: 완료 | X41: 2 | Y41: 4 | AA41: 1 | AG41: 1
...

Sheet 시트46
A1: 1 | B1: 이미지 대체 텍스트 | C1: 통이미지로 된 콘텐츠는 상세 정보를 alt 속성에 명확하게 작성해야 합니다.
C2: ex) 20대 20.2%, 30대 31.4%, 40대 24.1%, 50대 11.8%, 60대 5.4%
C3: 화면에 표시된 이미지의 텍스트 정보와 대체 텍스트가 동일하지 않더라도 해당 콘텐츠를 인식하는 데 큰 문제가 없을 경우, 접근성이 있는 것으로 판단
C4: 이미지의 시각적 정보와 대체 텍스트가 100% 일치하지 않더라도, 해당 콘텐츠가 전달하고자 하는 의미(목적)를 사용자가 충분히 이해할 수 있다면 접근성이 준수된 것으로 간주합니다. ex) 지도 이미지 내에 "주차장 입구는 건물 뒤편에 있습니다"라는 텍스트가 이미지에 포함된 경우 alt="우리 회사 찾아오시는 길 지도"
A5: 2 | B5: 키보드 접근성 | C5: 키보드 Tab 키만으로 상세페이지 내 모든 링크와 버튼에 접근해야 합니다.
A7: 3 | B7: 이모지 정보 전달용 or 장식용 | C7: 이모지는 내용 전달에 필수가 아니라면 스크린 리더가 이모지를 읽지 않도록 숨겨야 합니다.

Sheet 시트43
A1: 최종
A2: 조윤영 ★
A3: 목표 | B3: 세부추진계획 | C3: 목표수준 | D3: 평가지표 | E3: 기한 | G3: 비중
A4: 운영업무 만족도 향상 및 실무 전문성 강화 | B4: - Google Docs 를 활용한 프로젝트 이슈관리 - 고객과의 적극 소통 및 협업부서와 협력 및 소통을 통한 불만 제로 - JS 숙련도 향상을 통한 퍼블리싱 업무 효율화 | C4: - 업무 일정 준수율 90% 이상 - 팀원 및 협업부서와 원활한 협업 및 불만 제로 - 고객 칭찬 및 만족도 향상 | D4: - 일정 준수율 100% - 협업 파트 및 고객 불만 제로 - 고객 불만 제로 | E4: 46325 | F4: 정성 | G4: 30
A5: 유플러스 운영 메뉴얼 상시 현행화 | B5: - BO모듈의 개발상황 체크 및 사용 메뉴얼 현행화 관리 플러스탭외 상시 이벤트 | C5: 운영 메뉴얼 최신화 유지를 하며 팀원과 인력교체시 활용 | D5: 현행화 수준 및 실무 활용도 | E5: 46325 | F5: 정량 | G5: 20
A6: 유플러스 플러스탭 안정화 및 모듈화 | B6: - 플러스탭 코드를 재사용가능한 수준으로 컴포넌트화 | C6: - 운영 소스 기반 소스로 표준화 - 스타일 커스터마이징으로 실무 적용 가능한 수준 | D6: 레포지토리에 배포후 실무 적용회수 3회 이상 | E6: 46325 | F6: 정량 | G6: 20
A7: AX활용한 업무효율향상 | B7: - AI도구를 활용한 이벤트 페이지 자동화 테스트 | C7: - 이미지 입력 → 운영용 HTML/CSS 자동 변환 및 실무 적용으로 업무시간 단축 | D7: - 실무 활용 최소 3회 이상 - 솔루션 사용 전후 업무효율 전후 시간 비교 증빙 | E7: 46325 | F7: 정량 | G7: 15
A8: 노코드 기반 어플리케이션 개발 | B8: - Cursor 및 Figma Maker 등 AI 툴을 활용한 앱 기획 - 실무 보조용 노코드 앱(예: 점심 메뉴 추천 등) 구현 - AI 툴을 활용한 기획-디자인-개발 통합 프로세스 검증 | C8: - 실제 구동 가능한 노코드 기반 앱 1건 완성 및 시연 - 단순 반복 업무 지원 또는 내부 테스트용 결과물 도출 | D8: 어플리케이션 결과물 제출 및 기술 검증 | E8: 10월 | F8: 정량 | G8: 15
A28: 조윤영
A29: 목표 | B29: 세부추진계획 | C29: 목표수준 | D29: 평가지표 | E29: 기한 | F29: 비중
A30: 운영업무 만족도 향상 및 실무 전문성 강화 | B30: - 담당 프로젝트 업무 수행 - Google Docs 업무 관리 - 고객과의 적극 소통 및 협업부서와 협력 및 소통을 통한 불만 제로 | C30: - 담당 업무 매뉴얼(UI 컴포넌트 포함) 최신 상태 유지 - 협업 부서 만족도 향상 | D30: - 일정 준수율 100% - 협업 파트 및 고객 불만 제로 | E30: 46325 | F30: 30
A31: 유플러스 운영 메뉴얼 상시 현행화 | B31: - BO모듈의 개발상황 체크 및 사용 메뉴얼 현행화 관리 플러스탭외 상시 이벤트 | C31: 운영 메뉴얼 최신화 유지를 하며 팀원과 인력교체시 활용 | D31: 현행화 수준 및 실무 활용도 | E31: 46325 | F31: 20
A32: 유플러스 플러스탭 안정화 및 모듈화 | B32: - 플러스탭 코드를 재사용가능한 수준으로 컴포넌트화 | C32: - 운영 소스 기반 소스로 표준화 - 스타일 커스터마이징으로 실무 적용 가능한 수준 | D32: 레포지토리에 배포후 실무 적용회수 3회 이상 | E32: 46325 | F32: 20
A33: AX활용한 업무효율향상 | B33: - AI도구를 활용한 이벤트 페이지 자동화 테스트 | C33: - 이미지 입력 → 운영용 HTML/CSS 자동 변환 및 실무 적용으로 업무시간 단축 | D33: - 실무 활용 최소 3회 이상 | E33: 46325 | F33: 15
A34: 노코드 기반 어플리케이션 개발 | B34: - Cursor 및 Figma Maker 등 AI 툴을 활용한 앱 기획 - 실무 보조용 노코드 앱(예: 점심 메뉴 추천 등) 구현 - AI 툴을 활용한 기획-디자인-개발 통합 프로세스 검증 | C34: - 실제 구동 가능한 노코드 기반 앱 1건 완성 및 시연 - 단순 반복 업무 지원 또는 내부 테스트용 결과물 도출 | D34: 어플리케이션 결과물 제출 및 기술 검증 | E34: 10월 | F34: 0.15
A38: 목표 | B38: 세부추진계획 | C38: 목표수준 | D38: 평가지표
A39: 운영업무 만족도 향상 및 실무 전문성 강화 | B39: - Google Docs 를 활용한 프로젝트 이슈관리 - 고객과의 적극 소통 및 협업부서와 협력 및 소통을 통한 불만 제로 - JS 숙련도 향상을 통한 퍼블리싱 업무 효율화 | C39: - 업무 일정 준수율 90% 이상 - 팀원 및 협업부서와 원활한 협업 및 불만 제로 - 고객 칭찬 및 만족도 향상 | D39: - 일정 준수율 100% - 협업 파트 및 고객 불만 제로 - 고객 불만 제로
A40: 운영 메뉴얼 상시 현행화 | B40: - BO모듈의 개발상황 체크 및 사용 메뉴얼 현행화 관리 플러스탭외 상시 이벤트 | C40: 운영 메뉴얼 최신화 유지를 하며 팀원과 인력교체시 활용 | D40: 현행화 수준 및 실무 활용도
A41: 플러스탭 안정화 및 모듈화 | B41: - 플러스탭 코드를 재사용가능한 수준으로 컴포넌트화 | C41: - 운영 소스 기반 소스로 표준화 - 스타일 커스터마이징으로 실무 적용 가능한 수준 | D41: 레포지토리에 배포후 실무 적용회수 3회 이상
A42: AX활용한 업무효율향상 | B42: - AI도구를 활용한 이벤트 페이지 자동화 테스트 | C42: - 이미지 입력 → 운영용 HTML/CSS 자동 변환 및 실무 적용으로 업무시간 단축 | D42: - 실무 활용 최소 3회 이상 - 솔루션 사용 전후 업무효율 전후 시간 비교 증빙
A43: 노코드 기반 어플리케이션 개발 | B43: - Cursor 및 Figma Maker 등 AI 툴을 활용한 앱 기획 - 실무 보조용 노코드 앱(예: 점심 메뉴 추천 등) 구현 - AI 툴을 활용한 기획-디자인-개발 통합 프로세스 검증 | C43: - 실제 구동 가능한 노코드 기반 앱 1건 완성 및 시연 - 단순 반복 업무 지원 또는 내부 테스트용 결과물 도출 | D43: 어플리케이션 결과물 제출 및 기술 검증
A49: 조윤영 ★
A50: 목표 | B50: 세부추진계획 | C50: 목표수준 | D50: 평가지표 | E50: 기한 | G50: 비중
A51: 운영업무 만족도 향상 및 실무 전문성 강화 | B51: - Google Docs 를 활용한 프로젝트 이슈관리 - 고객과의 적극 소통 및 협업부서와 협력 및 소통을 통한 불만 제로 - JS 숙련도 향상을 통한 퍼블리싱 업무 효율화 | C51: - 업무 일정 준수율 90% 이상 - 팀원 및 협업부서와 원활한 협업 및 불만 제로 - 고객 칭찬 및 만족도 향상 | D51: - 일정 준수율 100% - 협업 파트 및 고객 불만 제로 - 고객 불만 제로 | E51: 46325 | F51: 정성 | G51: 30
A52: 유플러스 운영 메뉴얼 상시 현행화 | B52: - BO모듈의 개발상황 체크 및 사용 메뉴얼 현행화 관리 플러스탭외 상시 이벤트 | C52: 운영 메뉴얼 최신화 유지를 하며 팀원과 인력교체시 활용 | D52: 현행화 수준 및 실무 활용도 | E52: 46325 | F52: 정량 | G52: 20
A53: 유플러스 플러스탭 안정화 및 모듈화 | B53: - 플러스탭 코드를 재사용가능한 수준으로 컴포넌트화 | C53: - 운영 소스 기반 소스로 표준화 - 스타일 커스터마이징으로 실무 적용 가능한 수준 | D53: 레포지토리에 배포후 실무 적용회수 3회 이상 | E53: 46325 | F53: 정량 | G53: 20
A54: AX활용한 업무효율향상 | B54: - AI도구를 활용한 이벤트 페이지 자동화 테스트 | C54: - 이미지 입력 → 운영용 HTML/CSS 자동 변환 및 실무 적용으로 업무시간 단축 | D54: - 실무 활용 최소 3회 이상 - 솔루션 사용 전후 업무효율 전후 시간 비교 증빙 | E54: 46325 | F54: 정량 | G54: 15
A55: 노코드 기반 어플리케이션 개발 | B55: - Cursor 및 Figma Maker 등 AI 툴을 활용한 앱 기획 - 실무 보조용 노코드 앱(예: 점심 메뉴 추천 등) 구현 - AI 툴을 활용한 기획-디자인-개발 통합 프로세스 검증 | C55: - 실제 구동 가능한 노코드 기반 앱 1건 완성 및 시연 - 단순 반복 업무 지원 또는 내부 테스트용 결과물 도출 | D55: 어플리케이션 결과물 제출 및 기술 검증 | E55: 10월 | F55: 정량 | G55: 15
